Workbook

Sheet Camada 1
A1: Fonte | B1: Ano | C1: Tipo | D1: Título | E1: Decisão C1 | F1: Motivo | G1: Código | H1: Duplicado
A2: Scopus | B2: 2026 | C2: Artigo | D2: Development and real-world deployment of a multi-agent system to support the operation of renewable energy communities | E2: =IFERROR(VLOOKUP(G2, 'Padronização'!A:C, 2, FALSE), "") -> ❌ | F2: =IFERROR(VLOOKUP(G2, 'Padronização'!A:C, 3, FALSE), "") -> Energia, grid, V2G; crise tratada como operação técnica | G2: E2
A3: Scopus | B3: 2026 | C3: Artigo | D3: When agents learn to think: Large language model-enhanced agent-based modeling for crowd evacuation in disaster scenarios | E3: ✅ | F3: =IFERROR(VLOOKUP(G3, 'Padronização'!A:C, 3, FALSE), "") -> ABM/MAS focado em comportamento humano cognitivo | G3: I2
A4: Scopus | B4: 2026 | C4: Artigo | D4: Optimization method for fire rescue equipment allocation based on fuzzy needs assessment and AnyLogic simulation | E4: ⚠️ | F4: =IFERROR(VLOOKUP(G4, 'Padronização'!A:C, 3, FALSE), "") -> Emergência sem evacuação clara | G4: M2
A5: Scopus | B5: 2026 | C5: Artigo | D5: Spatial and operational interventions for healthy cruise ship design using agent-based modelling | E5: ❌ | F5: =IFERROR(VLOOKUP(G5, 'Padronização'!A:C, 3, FALSE), "") -> Emergência em saúde com foco operacional / Operação hospitalar | G5: E8
A6: Scopus | B6: 2026 | C6: Artigo | D6: Dynamic Human-Vehicle Risk Assessment for Urban Flood Evacuations in Island Cities: The MUFE Framework Applied to Haidian Island, Haikou | E6: ✅ | F6: =IFERROR(VLOOKUP(G6, 'Padronização'!A:C, 3, FALSE), "") -> ABM/MAS focado em comportamento humano cognitivo | G6: I2
A7: Scopus | B7: 2026 | C7: Artigo | D7: Impact of the caregiver-to-resident ratio on evacuation efficiency in nursing homes: A simulation-based study | E7: ✅ | F7: =IFERROR(VLOOKUP(G7, 'Padronização'!A:C, 3, FALSE), "") -> ABM/MAS aplicado à evacuação | G7: I1
A8: Scopus | B8: 2026 | C8: Artigo | D8: Enhancing urban flood resilience through agent-based modeling of evacuation behaviors | E8: ✅ | F8: =IFERROR(VLOOKUP(G8, 'Padronização'!A:C, 3, FALSE), "") -> ABM/MAS focado em comportamento humano cognitivo | G8: I2
A9: Scopus | B9: 2026 | C9: Artigo | D9: Multi-agent deep reinforcement learning for group intelligence in emergency evacuation: A decentralized simulation-to-reality platform with perception-aware policies | E9: ✅ | F9: =IFERROR(VLOOKUP(G9, 'Padronização'!A:C, 3, FALSE), "") -> ABM/MAS aplicado à evacuação | G9: I1
A10: Scopus | B10: 2026 | C10: Artigo | D10: A multi-agent deep reinforcement learning model for crowd coordinated evacuation simulation in complex environments | E10: ✅ | F10: =IFERROR(VLOOKUP(G10, 'Padronização'!A:C, 3, FALSE), "") -> ABM/MAS aplicado à evacuação | G10: I1
A11: Scopus | B11: 2026 | C11: Artigo | D11: Assessing public space design at transport stations during emergency situations using a data-driven agent-based model | E11: ⚠️ | F11: =IFERROR(VLOOKUP(G11, 'Padronização'!A:C, 3, FALSE), "") -> Crise explícita com foco em infraestrutura | G11: M1
A12: Scopus | B12: 2026 | C12: Artigo | D12: Enhancing resilience of electric vehicle charging management in hydrogen–electric coupled distribution networks: A risk-characterization multi-agent reinforcement learning approach | E12: ❌ | F12: =IFERROR(VLOOKUP(G12, 'Padronização'!A:C, 3, FALSE), "") -> Não aborda cenário de crise ou desastre | G12: E6
A13: Scopus | B13: 2026 | C13: Artigo | D13: Enhancing evacuation safety in urban primary schools: an agent-based model integrating child development behaviour and health dynamics | E13: ✅ | F13: =IFERROR(VLOOKUP(G13, 'Padronização'!A:C, 3, FALSE), "") -> ABM/MAS aplicado à evacuação | G13: I1
A14: Scopus | B14: 2026 | C14: Conference Paper | D14: An Adaptative Agent-Based Model Metasystem for Emergency Departments | E14: ⚠️ | F14: =IFERROR(VLOOKUP(G14, 'Padronização'!A:C, 3, FALSE), "") -> Emergência sem evacuação clara | G14: M2
... A177: Scopus | B177: 2025 | C177: Conference Paper | D177: Impact of a Dynamic Nurse-to-Patient Ratio Policy in the ICU: a Hybrid Simulation Model | E177: ❌ | F177: =IFERROR(VLOOKUP(G177, 'Padronização'!A:C, 3, FALSE), "") -> Emergência em saúde com foco operacional / Operação hospitalar | G177: E8
A178: Scopus | B178: 2025 | C178: Conference Paper | D178: IMPACT OF A DYNAMIC NURSE-TO-PATIENT RATIO POLICY IN THE ICU: A HYBRID SIMULATION MODEL | E178: ❌ | F178: =IFERROR(VLOOKUP(G178, 'Padronização'!A:C, 3, FALSE), "") -> Emergência em saúde com foco operacional / Operação hospitalar | G178: E8 | H178: SIM
A179: Scopus | B179: 2025 | C179: Artigo | D179: Multi-Agent Q-Net Enhanced Coevolutionary Algorithm for Resource Allocation in Emergency Human-Machine Fusion UAV-MEC System | E179: ❌ | F179: =IFERROR(VLOOKUP(G179, 'Padronização'!A:C, 3, FALSE), "") -> Não aborda cenário de crise ou desastre | G179: E6
A180: Scopus | B180: 2025 | C180: Conference Paper | D180: Dynamic UAV Swarm Control in Disaster Recovery via GenAI-Based Graph Reinforcement Learning | E180: ❌ | F180: =IFERROR(VLOOKUP(G180, 'Padronização'!A:C, 3, FALSE), "") -> Não aborda cenário de crise ou desastre | G180: E6
A181: Scopus | B181: 2025 | C181: Artigo | D181: Mitigating direct and indirect costs of unexpected pandemics: a parallel vaccination strategy utilizing agent-based simulation | E181: ⚠️ | F181: =IFERROR(VLOOKUP(G181, 'Padronização'!A:C, 3, FALSE), "") -> Emergência sem evacuação clara | G181: M2
A182: Scopus | B182: 2025 | C182: Artigo | D182: Sentiment Evolution of Online Public Opinion of Emergency Situations in Railway Stations: A Case Study of Wuhan Railway Stations | E182: ❌ | F182: =IFERROR(VLOOKUP(G182, 'Padronização'!A:C, 3, FALSE), "") -> Não aborda cenário de crise ou desastre | G182: E6
A183: Scopus | B183: 2025 | C183: Conference Paper | D183: Preliminary Comparison of Different EDs Performance, Using Simulation | E183: ❌ | F183: =IFERROR(VLOOKUP(G183, 'Padronização'!A:C, 3, FALSE), "") -> Não aborda cenário de crise ou desastre | G183: E6
A184: Scopus | B184: 2025 | C184: Conference Paper | D184: Penalties as Feedback on AV Behaviour | E184: ❌ | F184: =IFERROR(VLOOKUP(G184, 'Padronização'!A:C, 3, FALSE), "") -> Não aborda cenário de crise ou desastre | G184: E6
A185: Scopus | B185: 2025 | C185: Artigo | D185: Emergency Control Method of Multi-Modal Passenger Flow in Urban Rail Transit | E185: ⚠️ | F185: =IFERROR(VLOOKUP(G185, 'Padronização'!A:C, 3, FALSE), "") -> Emergência sem evacuação clara | G185: M2
A186: Scopus | B186: 2025 | C186: Conference Paper | D186: A Novel Multi-Agent RL Approach in Priority-Aware UAV-Assisted Networks for AoI and Energy Consumption Minimization | E186: ❌ | F186: =IFERROR(VLOOKUP(G186, 'Padronização'!A:C, 3, FALSE), "") -> Não aborda cenário de crise ou desastre | G186: E6
A187: Scopus | B187: 2025 | C187: Artigo | D187: Early COVID-19 Pandemic Preparedness: Informing Public Health Interventions and Hospital Capacity Planning Through Participatory Hybrid Simulation Modeling | E187: ⚠️ | F187: =IFERROR(VLOOKUP(G187, 'Padronização'!A:C, 3, FALSE), "") -> Emergência sem evacuação clara | G187: M2
A188: Scopus | B188: 2025 | C188: Artigo | D188: Efficient Merging at Work Zones to Support Emergency Response in Mixed Traffic Environments: A Reward Weight Adjustment Method for Multi-Agent Reinforcement Learning | E188: ❌ | F188: =IFERROR(VLOOKUP(G188, 'Padronização'!A:C, 3, FALSE), "") -> Não aborda cenário de crise ou desastre | G188: E6
A189: Scopus | B189: 2025 | C189: Artigo | D189: Deep Reinforcement Learning-Based Intelligent Resource Management in Multi-UAVs-Assisted MEC Emergency Communication System | E189: ❌ | F189: =IFERROR(VLOOKUP(G189, 'Padronização'!A:C, 3, FALSE), "") -> Não aborda cenário de crise ou desastre | G189: E6
A190: Scopus | B190: 2025 | C190: Conference Paper | D190: Socratic: Enhancing Human Teamwork via AI-enabled Coaching | E190: ❌ | F190: =IFERROR(VLOOKUP(G190, 'Padronização'!A:C, 3, FALSE), "") -> Não aborda cenário de crise ou desastre | G190: E6
... A307: Scopus | B307: 2024 | C307: Artigo | D307: USING AGENT-BASED MODELING TO CALCULATE AN EASE SCORE: EVACUATION WITH ACCEPTABLE SIMPLICITY IN EMERGENCIES | E307: ✅ | F307: =IFERROR(VLOOKUP(G307, 'Padronização'!A:C, 3, FALSE), "") -> ABM/MAS aplicado à evacuação | G307: I1
A308: Scopus | B308: 2024 | C308: Conference Paper | D308: Using Agent-Based Modeling to Calculate an Ease Score: Evacuation with Acceptable Simplicity in Emergencies | E308: ✅ | F308: =IFERROR(VLOOKUP(G308, 'Padronização'!A:C, 3, FALSE), "") -> ABM/MAS aplicado à evacuação | G308: I1 | H308: SIM
A309: Scopus | B309: 2024 | C309: Conference Paper | D309: Integration of Emotional-Cognitive Architecture in ACT-R for Multi-Agent Social Dynamics for Disaster Response Simulation | E309: ✅ | F309: =IFERROR(VLOOKUP(G309, 'Padronização'!A:C, 3, FALSE), "") -> ABM/MAS focado em comportamento humano cognitivo | G309: I2
A310: Scopus | B310: 2024 | C310: Conference Paper | D310: Modeling Realistic Human Behavior in Disasters. A Rapid Literature Review of Agent-Based Models Reviews | E310: ⚠️ | F310: =IFERROR(VLOOKUP(G310, 'Padronização'!A:C, 3, FALSE), "") -> Emergência sem evacuação clara | G310: M2
A311: Scopus | B311: 2024 | C311: Artigo | D311: Agent-based modeling of high-rise building fires reveals self-rescue behaviors and better fire protection designs | E311: ✅ | F311: =IFERROR(VLOOKUP(G311, 'Padronização'!A:C, 3, FALSE), "") -> ABM/MAS focado em comportamento humano cognitivo | G311: I2
A312: Scopus | B312: 2024 | C312: Artigo | D312: Simulation-Based Analysis of Evacuation Information Sharing Systems Using Geographical Data | E312: ✅ | F312: =IFERROR(VLOOKUP(G312, 'Padronização'!A:C, 3, FALSE), "") -> ABM/MAS aplicado à evacuação | G312: I1
A313: Scopus | B313: 2024 | C313: Conference Paper | D313: Computer Modeling of Evacuation Patterns Comparison and Crowd Dynamics: A Use of NetLogo | E313: ⚠️ | F313: =IFERROR(VLOOKUP(G313, 'Padronização'!A:C, 3, FALSE), "") -> Emergência sem evacuação clara | G313: M2
A314: Scopus | B314: 2024 | C314: Artigo | D314: An agent-based model to simulate human responses to flash flood warnings for improving evacuation performance | E314: ✅ | F314: =IFERROR(VLOOKUP(G314, 'Padronização'!A:C, 3, FALSE), "") -> ABM/MAS aplicado à evacuação | G314: I1
A315: Scopus | B315: 2024 | C315: Artigo | D315: A Game-Theoretic Approach to Safe Crowd Evacuation in Emergencies | E315: ⚠️ | F315: =IFERROR(VLOOKUP(G315, 'Padronização'!A:C, 3, FALSE), "") -> Emergência sem evacuação clara | G315: M2
A316: Scopus | B316: 2024 | C316: Artigo | D316: Multi-agent-based human cognition simulation of Situation-aware earthquake emergency evacuation | E316: ✅ | F316: =IFERROR(VLOOKUP(G316, 'Padronização'!A:C, 3, FALSE), "") -> ABM/MAS aplicado à evacuação | G316: I1
A317: Scopus | B317: 2024 | C317: Conference Paper | D317: Architecture-oriented agent-based model (AOAM) for optimizing transport evacuation management and emergency medical assistance in the context of the war in Ukraine: challenges and prospects | E317: ✅ | F317: =IFERROR(VLOOKUP(G317, 'Padronização'!A:C, 3, FALSE), "") -> ABM/MAS aplicado à evacuação | G317: I1
A318: Scopus | B318: 2024 | C318: Conference Paper | D318: Experiment and path optimization on Large-Space Multi-Area crowd evacuation | E318: ⚠️ | F318: =IFERROR(VLOOKUP(G318, 'Padronização'!A:C, 3, FALSE), "") -> Emergência sem evacuação clara | G318: M2
...

Sheet Camada 2
A1: Fonte | B1: Ano | C1: Tipo | D1: Título | E1: Decisão C1 | F1: Motivo | G1: Código | H1: Tipo de Crise | I1: Escala | J1: C. Humano | K1: Ferramenta | L1: Disponível | M1: Score | N1: Prioridade
A2: Scopus | B2: 2026 | C2: Artigo | D2: When agents learn to think: Large language model-enhanced agent-based modeling for crowd evacuation in disaster scenarios | E2: ✅ | F2: =IFERROR(VLOOKUP(G2, 'Padronização'!A:C, 3, FALSE), "") -> ABM/MAS focado em comportamento humano cognitivo | G2: I2 | H2: Multirriscos | I2: Microescala | J2: Sim | K2: Python | L2: Sim | M2: =IF(H2="","", IF(OR(H2="tornado",H2="vulcão",H2="enchente",H2="terremoto",H2="tsunami",H2="incêndio",H2="furacão",H2="deslizamento",H2="i. químico",H2="i. nuclear",H2="ataque",H2="guerra",H2="multirriscos"),2,0)+ IF(OR(I2="cidade",I2="regional",I2="urbano"),2,0)+ IF(J2="sim",2,IF(J2="parcial",1,0))+ IF(OR(K2="NetLogo",K2="Mesa",K2="GAMA",K2="Unity",K2="MATLAB",K2="Python"),2,0)+ IF(L2="sim",1,-10) ) -> 7 | N2: =IF(M2="","",IF(M2<=0,"EXCLUIR", IF(M2>=8,"ALTÍSSIMA", IF(M2>=6,"ALTA", IF(M2>=4,"MÉDIA", "BAIXA"))))) -> ALTA
A3: Scopus | B3: 2026 | C3: Artigo | D3: Dynamic Human-Vehicle Risk Assessment for Urban Flood Evacuations in Island Cities: The MUFE Framework Applied to Haidian Island, Haikou | E3: ✅ | F3: =IFERROR(VLOOKUP(G3, 'Padronização'!A:C, 3, FALSE), "") -> ABM/MAS focado em comportamento humano cognitivo | G3: I2 | H3: Enchente | I3: Regional | J3: Sim | K3: Mesa | L3: Sim | M3: =IF(H3="","", IF(OR(H3="tornado",H3="vulcão",H3="enchente",H3="terremoto",H3="tsunami",H3="incêndio",H3="furacão",H3="deslizamento",H3="i. químico",H3="i. nuclear",H3="ataque",H3="guerra",H3="multirriscos"),2,0)+ IF(OR(I3="cidade",I3="regional",I3="urbano"),2,0)+ IF(J3="sim",2,IF(J3="parcial",1,0))+ IF(OR(K3="NetLogo",K3="Mesa",K3="GAMA",K3="Unity",K3="MATLAB",K3="Python"),2,0)+ IF(L3="sim",1,-10) ) -> 9 | N3: =IF(M3="","",IF(M3<=0,"EXCLUIR", IF(M3>=8,"ALTÍSSIMA", IF(M3>=6,"ALTA", IF(M3>=4,"MÉDIA", "BAIXA"))))) -> ALTÍSSIMA
A4: Scopus | B4: 2026 | C4: Artigo | D4: Impact of the caregiver-to-resident ratio on evacuation efficiency in nursing homes: A simulation-based study | E4: ✅ | F4: =IFERROR(VLOOKUP(G4, 'Padronização'!A:C, 3, FALSE), "") -> ABM/MAS aplicado à evacuação | G4: I1 | H4: Multirriscos | I4: Microescala | J4: Sim | K4: Não informado | L4: Sim | M4: =IF(H4="","", IF(OR(H4="tornado",H4="vulcão",H4="enchente",H4="terremoto",H4="tsunami",H4="incêndio",H4="furacão",H4="deslizamento",H4="i. químico",H4="i. nuclear",H4="ataque",H4="guerra",H4="multirriscos"),2,0)+ IF(OR(I4="cidade",I4="regional",I4="urbano"),2,0)+ IF(J4="sim",2,IF(J4="parcial",1,0))+ IF(OR(K4="NetLogo",K4="Mesa",K4="GAMA",K4="Unity",K4="MATLAB",K4="Python"),2,0)+ IF(L4="sim",1,-10) ) -> 5 | N4: =IF(M4="","",IF(M4<=0,"EXCLUIR", IF(M4>=8,"ALTÍSSIMA", IF(M4>=6,"ALTA", IF(M4>=4,"MÉDIA", "BAIXA"))))) -> MÉDIA
A5: Scopus | B5: 2026 | C5: Artigo | D5: Enhancing urban flood resilience through agent-based modeling of evacuation behaviors | E5: ✅ | F5: =IFERROR(VLOOKUP(G5, 'Padronização'!A:C, 3, FALSE), "") -> ABM/MAS focado em comportamento humano cognitivo | G5: I2 | H5: Enchente | I5: Regional | J5: Sim | K5: NetLogo | L5: Sim | M5: =IF(H5="","", IF(OR(H5="tornado",H5="vulcão",H5="enchente",H5="terremoto",H5="tsunami",H5="incêndio",H5="furacão",H5="deslizamento",H5="i. químico",H5="i. nuclear",H5="ataque",H5="guerra",H5="multirriscos"),2,0)+ IF(OR(I5="cidade",I5="regional",I5="urbano"),2,0)+ IF(J5="sim",2,IF(J5="parcial",1,0))+ IF(OR(K5="NetLogo",K5="Mesa",K5="GAMA",K5="Unity",K5="MATLAB",K5="Python"),2,0)+ IF(L5="sim",1,-10) ) -> 9 | N5: =IF(M5="","",IF(M5<=0,"EXCLUIR", IF(M5>=8,"ALTÍSSIMA", IF(M5>=6,"ALTA", IF(M5>=4,"MÉDIA", "BAIXA"))))) -> ALTÍSSIMA
A6: Scopus | B6: 2026 | C6: Artigo | D6: Multi-agent deep reinforcement learning for group intelligence in emergency evacuation: A decentralized simulation-to-reality platform with perception-aware policies | E6: ✅ | F6: =IFERROR(VLOOKUP(G6, 'Padronização'!A:C, 3, FALSE), "") -> ABM/MAS aplicado à evacuação | G6: I1 | H6: Multirriscos | I6: Regional | J6: Parcial | K6: Outro | L6: Sim | M6: =IF(H6="","", IF(OR(H6="tornado",H6="vulcão",H6="enchente",H6="terremoto",H6="tsunami",H6="incêndio",H6="furacão",H6="deslizamento",H6="i. químico",H6="i. nuclear",H6="ataque",H6="guerra",H6="multirriscos"),2,0)+ IF(OR(I6="cidade",I6="regional",I6="urbano"),2,0)+ IF(J6="sim",2,IF(J6="parcial",1,0))+ IF(OR(K6="NetLogo",K6="Mesa",K6="GAMA",K6="Unity",K6="MATLAB",K6="Python"),2,0)+ IF(L6="sim",1,-10) ) -> 6 | N6: =IF(M6="","",IF(M6<=0,"EXCLUIR", IF(M6>=8,"ALTÍSSIMA", IF(M6>=6,"ALTA", IF(M6>=4,"MÉDIA", "BAIXA"))))) -> ALTA
A7: Scopus | B7: 2026 | C7: Artigo | D7: A multi-agent deep reinforcement learning model for crowd coordinated evacuation simulation in complex environments | E7: ✅ | F7: =IFERROR(VLOOKUP(G7, 'Padronização'!A:C, 3, FALSE), "") -> ABM/MAS aplicado à evacuação | G7: I1 | H7: Multirriscos | I7: Microescala | J7: Parcial | K7: Outro | L7: Sim | M7: =IF(H7="","", IF(OR(H7="tornado",H7="vulcão",H7="enchente",H7="terremoto",H7="tsunami",H7="incêndio",H7="furacão",H7="deslizamento",H7="i. químico",H7="i. nuclear",H7="ataque",H7="guerra",H7="multirriscos"),2,0)+ IF(OR(I7="cidade",I7="regional",I7="urbano"),2,0)+ IF(J7="sim",2,IF(J7="parcial",1,0))+ IF(OR(K7="NetLogo",K7="Mesa",K7="GAMA",K7="Unity",K7="MATLAB",K7="Python"),2,0)+ IF(L7="sim",1,-10) ) -> 4 | N7: =IF(M7="","",IF(M7<=0,"EXCLUIR", IF(M7>=8,"ALTÍSSIMA", IF(M7>=6,"ALTA", IF(M7>=4,"MÉDIA", "BAIXA"))))) -> MÉDIA
A8: Scopus | B8: 2026 | C8: Artigo | D8: Enhancing evacuation safety in urban primary schools: an agent-based model integrating child development behaviour and health dynamics | E8: ✅ | F8: =IFERROR(VLOOKUP(G8, 'Padronização'!A:C, 3, FALSE), "") -> ABM/MAS aplicado à evacuação | G8: I1 | H8: Incêndio | I8: Microescala | J8: Sim | K8: NetLogo | L8: Sim | M8: =IF(H8="","", IF(OR(H8="tornado",H8="vulcão",H8="enchente",H8="terremoto",H8="tsunami",H8="incêndio",H8="furacão",H8="deslizamento",H8="i. químico",H8="i. nuclear",H8="ataque",H8="guerra",H8="multirriscos"),2,0)+ IF(OR(I8="cidade",I8="regional",I8="urbano"),2,0)+ IF(J8="sim",2,IF(J8="parcial",1,0))+ IF(OR(K8="NetLogo",K8="Mesa",K8="GAMA",K8="Unity",K8="MATLAB",K8="Python"),2,0)+ IF(L8="sim",1,-10) ) -> 7 | N8: =IF(M8="","",IF(M8<=0,"EXCLUIR", IF(M8>=8,"ALTÍSSIMA", IF(M8>=6,"ALTA", IF(M8>=4,"MÉDIA", "BAIXA"))))) -> ALTA
A9: Scopus | B9: 2026 | C9: Conference Paper | D9: Multi-agents UAV Coordination for Evacuation Support in Disaster-Affected Areas | E9: ✅ | F9: =IFERROR(VLOOKUP(G9, 'Padronização'!A:C, 3, FALSE), "") -> ABM/MAS focado em comportamento humano cognitivo | G9: I2 | H9: Não Relevante | L9: Não | M9: =IF(H9="","", IF(OR(H9="tornado",H9="vulcão",H9="enchente",H9="terremoto",H9="tsunami",H9="incêndio",H9="furacão",H9="deslizamento",H9="i. químico",H9="i. nuclear",H9="ataque",H9="guerra",H9="multirriscos"),2,0)+ IF(OR(I9="cidade",I9="regional",I9="urbano"),2,0)+ IF(J9="sim",2,IF(J9="parcial",1,0))+ IF(OR(K9="NetLogo",K9="Mesa",K9="GAMA",K9="Unity",K9="MATLAB",K9="Python"),2,0)+ IF(L9="sim",1,-10) ) -> -10 | N9: =IF(M9="","",IF(M9<=0,"EXCLUIR", IF(M9>=8,"ALTÍSSIMA", IF(M9>=6,"ALTA", IF(M9>=4,"MÉDIA", "BAIXA"))))) -> EXCLUIR
A10: Scopus | B10: 2025 | C10: Artigo | D10: Improving emergency evacuation capacity for subway stations based on agent-based modelling | E10: ✅ | F10: =IFERROR(VLOOKUP(G10, 'Padronização'!A:C, 3, FALSE), "") -> ABM/MAS aplicado à evacuação | G10: I1 | H10: Multirriscos | I10: Microescala | J10: Sim | K10: Não informado | L10: Sim | M10: =IF(H10="","", IF(OR(H10="tornado",H10="vulcão",H10="enchente",H10="terremoto",H10="tsunami",H10="incêndio",H10="furacão",H10="deslizamento",H10="i. químico",H10="i. nuclear",H10="ataque",H10="guerra",H10="multirriscos"),2,0)+ IF(OR(I10="cidade",I10="regional",I10="urbano"),2,0)+ IF(J10="sim",2,IF(J10="parcial",1,0))+ IF(OR(K10="NetLogo",K10="Mesa",K10="GAMA",K10="Unity",K10="MATLAB",K10="Python"),2,0)+ IF(L10="sim",1,-10) ) -> 5 | N10: =IF(M10="","",IF(M10<=0,"EXCLUIR", IF(M10>=8,"ALTÍSSIMA", IF(M10>=6,"ALTA", IF(M10>=4,"MÉDIA", "BAIXA"))))) -> MÉDIA
A11: Scopus | B11: 2025 | C11: Artigo | D11: Urban waterlogging disaster risk evaluation framework based on complex network and agent-based model: a case study of Zhengzhou, China | E11: ✅ | F11: =IFERROR(VLOOKUP(G11, 'Padronização'!A:C, 3, FALSE), "") -> ABM/MAS focado em comportamento humano cognitivo | G11: I2 | H11: Enchente | I11: Regional | J11: Sim | K11: NetLogo | L11: Sim | M11: =IF(H11="","", IF(OR(H11="tornado",H11="vulcão",H11="enchente",H11="terremoto",H11="tsunami",H11="incêndio",H11="furacão",H11="deslizamento",H11="i. químico",H11="i. nuclear",H11="ataque",H11="guerra",H11="multirriscos"),2,0)+ IF(OR(I11="cidade",I11="regional",I11="urbano"),2,0)+ IF(J11="sim",2,IF(J11="parcial",1,0))+ IF(OR(K11="NetLogo",K11="Mesa",K11="GAMA",K11="Unity",K11="MATLAB",K11="Python"),2,0)+ IF(L11="sim",1,-10) ) -> 9 | N11: =IF(M11="","",IF(M11<=0,"EXCLUIR", IF(M11>=8,"ALTÍSSIMA", IF(M11>=6,"ALTA", IF(M11>=4,"MÉDIA", "BAIXA"))))) -> ALTÍSSIMA
A12: Scopus | B12: 2025 | C12: Artigo | D12: FRAMe: Empirically informed agent-based modeling of flood resilience in the Mekong River Basin | E12: ✅ | F12: =IFERROR(VLOOKUP(G12, 'Padronização'!A:C, 3, FALSE), "") -> ABM/MAS focado em comportamento humano cognitivo | G12: I2 | H12: Enchente | I12: Regional | J12: Sim | K12: NetLogo | L12: Sim | M12: =IF(H12="","", IF(OR(H12="tornado",H12="vulcão",H12="enchente",H12="terremoto",H12="tsunami",H12="incêndio",H12="furacão",H12="deslizamento",H12="i. químico",H12="i. nuclear",H12="ataque",H12="guerra",H12="multirriscos"),2,0)+ IF(OR(I12="cidade",I12="regional",I12="urbano"),2,0)+ IF(J12="sim",2,IF(J12="parcial",1,0))+ IF(OR(K12="NetLogo",K12="Mesa",K12="GAMA",K12="Unity",K12="MATLAB",K12="Python"),2,0)+ IF(L12="sim",1,-10) ) -> 9 | N12: =IF(M12="","",IF(M12<=0,"EXCLUIR", IF(M12>=8,"ALTÍSSIMA", IF(M12>=6,"ALTA", IF(M12>=4,"MÉDIA", "BAIXA"))))) -> ALTÍSSIMA
A13: Scopus | B13: 2025 | C13: Artigo | D13: Comparison of crowd evacuation efficiency under static signage and dynamic personnel guidance from an emotional contagion perspective | E13: ✅ | F13: =IFERROR(VLOOKUP(G13, 'Padronização'!A:C, 3, FALSE), "") -> ABM/MAS aplicado à evacuação | G13: I1 | H13: Multirriscos | I13: Regional | J13: Sim | K13: NetLogo | L13: Sim | M13: =IF(H13="","", IF(OR(H13="tornado",H13="vulcão",H13="enchente",H13="terremoto",H13="tsunami",H13="incêndio",H13="furacão",H13="deslizamento",H13="i. químico",H13="i. nuclear",H13="ataque",H13="guerra",H13="multirriscos"),2,0)+ IF(OR(I13="cidade",I13="regional",I13="urbano"),2,0)+ IF(J13="sim",2,IF(J13="parcial",1,0))+ IF(OR(K13="NetLogo",K13="Mesa",K13="GAMA",K13="Unity",K13="MATLAB",K13="Python"),2,0)+ IF(L13="sim",1,-10) ) -> 9 | N13: =IF(M13="","",IF(M13<=0,"EXCLUIR", IF(M13>=8,"ALTÍSSIMA", IF(M13>=6,"ALTA", IF(M13>=4,"MÉDIA", "BAIXA"))))) -> ALTÍSSIMA
A14: Scopus | B14: 2025 | C14: Artigo | D14: Psychological stress on human mobility and emergency evacuation in disaster response | E14: ✅ | F14: =IFERROR(VLOOKUP(G14, 'Padronização'!A:C, 3, FALSE), "") -> ABM/MAS aplicado à evacuação | G14: I1 | H14: Multirriscos | I14: Regional | J14: Sim | K14: Outro | L14: Sim | M14: =IF(H14="","", IF(OR(H14="tornado",H14="vulcão",H14="enchente",H14="terremoto",H14="tsunami",H14="incêndio",H14="furacão",H14="deslizamento",H14="i. químico",H14="i. nuclear",H14="ataque",H14="guerra",H14="multirriscos"),2,0)+ IF(OR(I14="cidade",I14="regional",I14="urbano"),2,0)+ IF(J14="sim",2,IF(J14="parcial",1,0))+ IF(OR(K14="NetLogo",K14="Mesa",K14="GAMA",K14="Unity",K14="MATLAB",K14="Python"),2,0)+ IF(L14="sim",1,-10) ) -> 7 | N14: =IF(M14="","",IF(M14<=0,"EXCLUIR", IF(M14>=8,"ALTÍSSIMA", IF(M14>=6,"ALTA", IF(M14>=4,"MÉDIA", "BAIXA"))))) -> ALTA
A15: Scopus | B15: 2025 | C15: Artigo | D15: Large-language-model-driven agents for fire evacuation simulation in a cellular automata environment | E15: ✅ | F15: =IFERROR(VLOOKUP(G15, 'Padronização'!A:C, 3, FALSE), "") -> ABM/MAS aplicado à evacuação | G15: I1 | H15: Incêndio | I15: Microescala | J15: Sim | K15: Não informado | L15: Sim | M15: =IF(H15="","", IF(OR(H15="tornado",H15="vulcão",H15="enchente",H15="terremoto",H15="tsunami",H15="incêndio",H15="furacão",H15="deslizamento",H15="i. químico",H15="i. nuclear",H15="ataque",H15="guerra",H15="multirriscos"),2,0)+ IF(OR(I15="cidade",I15="regional",I15="urbano"),2,0)+ IF(J15="sim",2,IF(J15="parcial",1,0))+ IF(OR(K15="NetLogo",K15="Mesa",K15="GAMA",K15="Unity",K15="MATLAB",K15="Python"),2,0)+ IF(L15="sim",1,-10) ) -> 5 | N15: =IF(M15="","",IF(M15<=0,"EXCLUIR", IF(M15>=8,"ALTÍSSIMA", IF(M15>=6,"ALTA", IF(M15>=4,"MÉDIA", "BAIXA"))))) -> MÉDIA
A16: Scopus | B16: 2025 | C16: Artigo | D16: Enhancing local flood resilience: A participatory simulation-game framework for evacuation planning in Thailand | E16: ✅ | F16: =IFERROR(VLOOKUP(G16, 'Padronização'!A:C, 3, FALSE), "") -> ABM/MAS aplicado à evacuação | G16: I1 | H16: Enchente | I16: Regional | J16: Sim | K16: GAMA | L16: Sim | M16: =IF(H16="","", IF(OR(H16="tornado",H16="vulcão",H16="enchente",H16="terremoto",H16="tsunami",H16="incêndio",H16="furacão",H16="deslizamento",H16="i. químico",H16="i. nuclear",H16="ataque",H16="guerra",H16="multirriscos"),2,0)+ IF(OR(I16="cidade",I16="regional",I16="urbano"),2,0)+ IF(J16="sim",2,IF(J16="parcial",1,0))+ IF(OR(K16="NetLogo",K16="Mesa",K16="GAMA",K16="Unity",K16="MATLAB",K16="Python"),2,0)+ IF(L16="sim",1,-10) ) -> 9 | N16: =IF(M16="","",IF(M16<=0,"EXCLUIR", IF(M16>=8,"ALTÍSSIMA", IF(M16>=6,"ALTA", IF(M16>=4,"MÉDIA", "BAIXA"))))) -> ALTÍSSIMA
A17: Scopus | B17: 2025 | C17: Artigo | D17: Optimizing Evacuation for Disabled Pedestrians with Heterogeneous Speeds: A Floor Field Cellular Automaton and Reinforcement Learning Approach | E17: ✅ | F17: =IFERROR(VLOOKUP(G17, 'Padronização'!A:C, 3, FALSE), "") -> ABM/MAS aplicado à evacuação | G17: I1 | H17: Multirriscos | I17: Microescala | J17: Parcial | K17: Não informado | L17: Sim | M17: =IF(H17="","", IF(OR(H17="tornado",H17="vulcão",H17="enchente",H17="terremoto",H17="tsunami",H17="incêndio",H17="furacão",H17="deslizamento",H17="i. químico",H17="i. nuclear",H17="ataque",H17="guerra",H17="multirriscos"),2,0)+ IF(OR(I17="cidade",I17="regional",I17="urbano"),2,0)+ IF(J17="sim",2,IF(J17="parcial",1,0))+ IF(OR(K17="NetLogo",K17="Mesa",K17="GAMA",K17="Unity",K17="MATLAB",K17="Python"),2,0)+ IF(L17="sim",1,-10) ) -> 4 | N17: =IF(M17="","",IF(M17<=0,"EXCLUIR", IF(M17>=8,"ALTÍSSIMA", IF(M17>=6,"ALTA", IF(M17>=4,"MÉDIA", "BAIXA"))))) -> MÉDIA
A18: Scopus | B18: 2025 | C18: Artigo | D18: ABMS-Driven Reinforcement Learning for Dynamic Resource Allocation in Mass Casualty Incidents † | E18: ✅ | F18: =IFERROR(VLOOKUP(G18, 'Padronização'!A:C, 3, FALSE), "") -> ABM/MAS focado em comportamento humano cognitivo | G18: I2 | H18: Multirriscos | I18: Regional | J18: Não | K18: Mesa | L18: Sim | M18: =IF(H18="","", IF(OR(H18="tornado",H18="vulcão",H18="enchente",H18="terremoto",H18="tsunami",H18="incêndio",H18="furacão",H18="deslizamento",H18="i. químico",H18="i. nuclear",H18="ataque",H18="guerra",H18="multirriscos"),2,0)+ IF(OR(I18="cidade",I18="regional",I18="urbano"),2,0)+ IF(J18="sim",2,IF(J18="parcial",1,0))+ IF(OR(K18="NetLogo",K18="Mesa",K18="GAMA",K18="Unity",K18="MATLAB",K18="Python"),2,0)+ IF(L18="sim",1,-10) ) -> 7 | N18: =IF(M18="","",IF(M18<=0,"EXCLUIR", IF(M18>=8,"ALTÍSSIMA", IF(M18>=6,"ALTA", IF(M18>=4,"MÉDIA", "BAIXA"))))) -> ALTA
A19: Scopus | B19: 2025 | C19: Artigo | D19: Evaluating strategies for single to multi-risk mitigation in urban public open spaces: A behavioural simulation-based approach applied to Italian typological historical urban squares | E19: ✅ | F19: =IFERROR(VLOOKUP(G19, 'Padronização'!A:C, 3, FALSE), "") -> ABM/MAS focado em comportamento humano cognitivo | G19: I2 | H19: Multirriscos | I19: Microescala | J19: Sim | K19: NetLogo | L19: Sim | M19: =IF(H19="","", IF(OR(H19="tornado",H19="vulcão",H19="enchente",H19="terremoto",H19="tsunami",H19="incêndio",H19="furacão",H19="deslizamento",H19="i. químico",H19="i. nuclear",H19="ataque",H19="guerra",H19="multirriscos"),2,0)+ IF(OR(I19="cidade",I19="regional",I19="urbano"),2,0)+ IF(J19="sim",2,IF(J19="parcial",1,0))+ IF(OR(K19="NetLogo",K19="Mesa",K19="GAMA",K19="Unity",K19="MATLAB",K19="Python"),2,0)+ IF(L19="sim",1,-10) ) -> 7 | N19: =IF(M19="","",IF(M19<=0,"EXCLUIR", IF(M19>=8,"ALTÍSSIMA", IF(M19>=6,"ALTA", IF(M19>=4,"MÉDIA", "BAIXA"))))) -> ALTA
A20: Scopus | B20: 2025 | C20: Artigo | D20: An evacuation guidance approach based on multi-agent shared Q-learning | E20: ✅ | F20: =IFERROR(VLOOKUP(G20, 'Padronização'!A:C, 3, FALSE), "") -> ABM/MAS aplicado à evacuação | G20: I1 | H20: Multirriscos | I20: Microescala | J20: Sim | K20: Não informado | L20: Sim | M20: =IF(H20="","", IF(OR(H20="tornado",H20="vulcão",H20="enchente",H20="terremoto",H20="tsunami",H20="incêndio",H20="furacão",H20="deslizamento",H20="i. químico",H20="i. nuclear",H20="ataque",H20="guerra",H20="multirriscos"),2,0)+ IF(OR(I20="cidade",I20="regional",I20="urbano"),2,0)+ IF(J20="sim",2,IF(J20="parcial",1,0))+ IF(OR(K20="NetLogo",K20="Mesa",K20="GAMA",K20="Unity",K20="MATLAB",K20="Python"),2,0)+ IF(L20="sim",1,-10) ) -> 5 | N20: =IF(M20="","",IF(M20<=0,"EXCLUIR", IF(M20>=8,"ALTÍSSIMA", IF(M20>=6,"ALTA", IF(M20>=4,"MÉDIA", "BAIXA"))))) -> MÉDIA
A21: Scopus | B21: 2025 | C21: Artigo | D21: Assessment of the impact of temporal and spatial factors on the emergency evacuation capacity of external spaces in high-density urban communities during earthquake disasters | E21: ✅ | F21: =IFERROR(VLOOKUP(G21, 'Padronização'!A:C, 3, FALSE), "") -> ABM/MAS aplicado à evacuação | G21: I1 | H21: Terremoto | I21: Regional | J21: Parcial | K21: Python | L21: Sim | M21: =IF(H21="","", IF(OR(H21="tornado",H21="vulcão",H21="enchente",H21="terremoto",H21="tsunami",H21="incêndio",H21="furacão",H21="deslizamento",H21="i. químico",H21="i. nuclear",H21="ataque",H21="guerra",H21="multirriscos"),2,0)+ IF(OR(I21="cidade",I21="regional",I21="urbano"),2,0)+ IF(J21="sim",2,IF(J21="parcial",1,0))+ IF(OR(K21="NetLogo",K21="Mesa",K21="GAMA",K21="Unity",K21="MATLAB",K21="Python"),2,0)+ IF(L21="sim",1,-10) ) -> 8 | N21: =IF(M21="","",IF(M21<=0,"EXCLUIR", IF(M21>=8,"ALTÍSSIMA", IF(M21>=6,"ALTA", IF(M21>=4,"MÉDIA", "BAIXA"))))) -> ALTÍSSIMA
... A25: Scopus | B25: 2025 | C25: Conference Paper | D25: Microscopic simulation of the elderly evacuation in nursing homes | E25: ✅ | F25: =IFERROR(VLOOKUP(G25, 'Padronização'!A:C, 3, FALSE), "") -> ABM/MAS aplicado à evacuação | G25: I1 | H25: Multirriscos | I25: Regional | J25: Parcial | K25: Não informado | L25: Sim | M25: =IF(H25="","", IF(OR(H25="tornado",H25="vulcão",H25="enchente",H25="terremoto",H25="tsunami",H25="incêndio",H25="furacão",H25="deslizamento",H25="i. químico",H25="i. nuclear",H25="ataque",H25="guerra",H25="multirriscos"),2,0)+ IF(OR(I25="cidade",I25="regional",I25="urbano"),2,0)+ IF(J25="sim",2,IF(J25="parcial",1,0))+ IF(OR(K25="NetLogo",K25="Mesa",K25="GAMA",K25="Unity",K25="MATLAB",K25="Python"),2,0)+ IF(L25="sim",1,-10) ) -> 6 | N25: =IF(M25="","",IF(M25<=0,"EXCLUIR", IF(M25>=8,"ALTÍSSIMA", IF(M25>=6,"ALTA", IF(M25>=4,"MÉDIA", "BAIXA"))))) -> ALTA
A26: Scopus | B26: 2025 | C26: Artigo | D26: Optimizing emergency evacuation control strategies for university turnstiles in crisis situations | 突发事件下高校闸机应急疏散管控策略 | E26: ✅ | F26: =IFERROR(VLOOKUP(G26, 'Padronização'!A:C, 3, FALSE), "") -> ABM/MAS aplicado à evacuação | G26: I1 | H26: Não Relevante | L26: Não | M26: =IF(H26="","", IF(OR(H26="tornado",H26="vulcão",H26="enchente",H26="terremoto",H26="tsunami",H26="incêndio",H26="furacão",H26="deslizamento",H26="i. químico",H26="i. nuclear",H26="ataque",H26="guerra",H26="multirriscos"),2,0)+ IF(OR(I26="cidade",I26="regional",I26="urbano"),2,0)+ IF(J26="sim",2,IF(J26="parcial",1,0))+ IF(OR(K26="NetLogo",K26="Mesa",K26="GAMA",K26="Unity",K26="MATLAB",K26="Python"),2,0)+ IF(L26="sim",1,-10) ) -> -10 | N26: =IF(M26="","",IF(M26<=0,"EXCLUIR", IF(M26>=8,"ALTÍSSIMA", IF(M26>=6,"ALTA", IF(M26>=4,"MÉDIA", "BAIXA"))))) -> EXCLUIR
A27: Scopus | B27: 2025 | C27: Artigo | D27: Resident Participation in Flood Response: A Machine Learning and Agent-Based Simulation Study of Zhengzhou, China | E27: ✅ | F27: =IFERROR(VLOOKUP(G27, 'Padronização'!A:C, 3, FALSE), "") -> ABM/MAS focado em comportamento humano cognitivo | G27: I2 | H27: Enchente | I27: Regional | J27: Sim | K27: Outro | L27: Sim | M27: =IF(H27="","", IF(OR(H27="tornado",H27="vulcão",H27="enchente",H27="terremoto",H27="tsunami",H27="incêndio",H27="furacão",H27="deslizamento",H27="i. químico",H27="i. nuclear",H27="ataque",H27="guerra",H27="multirriscos"),2,0)+ IF(OR(I27="cidade",I27="regional",I27="urbano"),2,0)+ IF(J27="sim",2,IF(J27="parcial",1,0))+ IF(OR(K27="NetLogo",K27="Mesa",K27="GAMA",K27="Unity",K27="MATLAB",K27="Python"),2,0)+ IF(L27="sim",1,-10) ) -> 7 | N27: =IF(M27="","",IF(M27<=0,"EXCLUIR", IF(M27>=8,"ALTÍSSIMA", IF(M27>=6,"ALTA", IF(M27>=4,"MÉDIA", "BAIXA"))))) -> ALTA
A28: Scopus | B28: 2025 | C28: Artigo | D28: Integrated multi-agent-based outpatient building fire response modeling for risk-driven resource use and retrofitting strategies: A case study | E28: ✅ | F28: =IFERROR(VLOOKUP(G28, 'Padronização'!A:C, 3, FALSE), "") -> ABM/MAS aplicado à evacuação | G28: I1 | H28: Incêndio | I28: Microescala | J28: Parcial | K28: Outro | L28: Sim | M28: =IF(H28="","", IF(OR(H28="tornado",H28="vulcão",H28="enchente",H28="terremoto",H28="tsunami",H28="incêndio",H28="furacão",H28="deslizamento",H28="i. químico",H28="i. nuclear",H28="ataque",H28="guerra",H28="multirriscos"),2,0)+ IF(OR(I28="cidade",I28="regional",I28="urbano"),2,0)+ IF(J28="sim",2,IF(J28="parcial",1,0))+ IF(OR(K28="NetLogo",K28="Mesa",K28="GAMA",K28="Unity",K28="MATLAB",K28="Python"),2,0)+ IF(L28="sim",1,-10) ) -> 4 | N28: =IF(M28="","",IF(M28<=0,"EXCLUIR", IF(M28>=8,"ALTÍSSIMA", IF(M28>=6,"ALTA", IF(M28>=4,"MÉDIA", "BAIXA"))))) -> MÉDIA
A29: Scopus | B29: 2025 | C29: Artigo | D29: Analyzing wildfire evacuation dynamics with agent-based modeling in damaged road networks | E29: ✅ | F29: =IFERROR(VLOOKUP(G29, 'Padronização'!A:C, 3, FALSE), "") -> ABM/MAS aplicado à evacuação | G29: I1 | H29: Incêndio | I29: Regional | J29: Sim | K29: Outro | L29: Sim | M29: =IF(H29="","", IF(OR(H29="tornado",H29="vulcão",H29="enchente",H29="terremoto",H29="tsunami",H29="incêndio",H29="furacão",H29="deslizamento",H29="i. químico",H29="i. nuclear",H29="ataque",H29="guerra",H29="multirriscos"),2,0)+ IF(OR(I29="cidade",I29="regional",I29="urbano"),2,0)+ IF(J29="sim",2,IF(J29="parcial",1,0))+ IF(OR(K29="NetLogo",K29="Mesa",K29="GAMA",K29="Unity",K29="MATLAB",K29="Python"),2,0)+ IF(L29="sim",1,-10) ) -> 7 | N29: =IF(M29="","",IF(M29<=0,"EXCLUIR", IF(M29>=8,"ALTÍSSIMA", IF(M29>=6,"ALTA", IF(M29>=4,"MÉDIA", "BAIXA"))))) -> ALTA
A30: Scopus | B30: 2025 | C30: Artigo | D30: An agent-based model for simulating cooperative behavior in crowd evacuation during toxic gas terrorist attacks | E30: ✅ | F30: =IFERROR(VLOOKUP(G30, 'Padronização'!A:C, 3, FALSE), "") -> ABM/MAS aplicado à evacuação | G30: I1 | H30: I. Químico | I30: Microescala | J30: Sim | K30: NetLogo | L30: Sim | M30: =IF(H30="","", IF(OR(H30="tornado",H30="vulcão",H30="enchente",H30="terremoto",H30="tsunami",H30="incêndio",H30="furacão",H30="deslizamento",H30="i. químico",H30="i. nuclear",H30="ataque",H30="guerra",H30="multirriscos"),2,0)+ IF(OR(I30="cidade",I30="regional",I30="urbano"),2,0)+ IF(J30="sim",2,IF(J30="parcial",1,0))+ IF(OR(K30="NetLogo",K30="Mesa",K30="GAMA",K30="Unity",K30="MATLAB",K30="Python"),2,0)+ IF(L30="sim",1,-10) ) -> 7 | N30: =IF(M30="","",IF(M30<=0,"EXCLUIR", IF(M30>=8,"ALTÍSSIMA", IF(M30>=6,"ALTA", IF(M30>=4,"MÉDIA", "BAIXA"))))) -> ALTA
A31: Scopus | B31: 2025 | C31: Artigo | D31: Dynamic flood evacuation modelling for coastal cities: A case study of Shanghai | E31: ✅ | F31: =IFERROR(VLOOKUP(G31, 'Padronização'!A:C, 3, FALSE), "") -> ABM/MAS aplicado à evacuação | G31: I1 | H31: Enchente | I31: Regional | J31: Sim | K31: NetLogo | L31: Sim | M31: =IF(H31="","", IF(OR(H31="tornado",H31="vulcão",H31="enchente",H31="terremoto",H31="tsunami",H31="incêndio",H31="furacão",H31="deslizamento",H31="i. químico",H31="i. nuclear",H31="ataque",H31="guerra",H31="multirriscos"),2,0)+ IF(OR(I31="cidade",I31="regional",I31="urbano"),2,0)+ IF(J31="sim",2,IF(J31="parcial",1,0))+ IF(OR(K31="NetLogo",K31="Mesa",K31="GAMA",K31="Unity",K31="MATLAB",K31="Python"),2,0)+ IF(L31="sim",1,-10) ) -> 9 | N31: =IF(M31="","",IF(M31<=0,"EXCLUIR", IF(M31>=8,"ALTÍSSIMA", IF(M31>=6,"ALTA", IF(M31>=4,"MÉDIA", "BAIXA"))))) -> ALTÍSSIMA
A32: Scopus | B32: 2025 | C32: Artigo | D32: AI-driven decision-making for water resource planning and hazard mitigation using automated multi-agents | E32: ✅ | F32: =IFERROR(VLOOKUP(G32, 'Padronização'!A:C, 3, FALSE), "") -> ABM/MAS focado em comportamento humano cognitivo | G32: I2 | H32: Multirriscos | I32: Regional | J32: Sim | K32: Outro | L32: Sim | M32: =IF(H32="","", IF(OR(H32="tornado",H32="vulcão",H32="enchente",H32="terremoto",H32="tsunami",H32="incêndio",H32="furacão",H32="deslizamento",H32="i. químico",H32="i. nuclear",H32="ataque",H32="guerra",H32="multirriscos"),2,0)+ IF(OR(I32="cidade",I32="regional",I32="urbano"),2,0)+ IF(J32="sim",2,IF(J32="parcial",1,0))+ IF(OR(K32="NetLogo",K32="Mesa",K32="GAMA",K32="Unity",K32="MATLAB",K32="Python"),2,0)+ IF(L32="sim",1,-10) ) -> 7 | N32: =IF(M32="","",IF(M32<=0,"EXCLUIR", IF(M32>=8,"ALTÍSSIMA", IF(M32>=6,"ALTA", IF(M32>=4,"MÉDIA", "BAIXA"))))) -> ALTA
A33: Scopus | B33: 2025 | C33: Artigo | D33: Multi-agent cooperation simulation for urban flood disaster emergency rescue | 基于城市洪涝灾害应急救援的多主体协同仿真 | E33: ✅ | F33: =IFERROR(VLOOKUP(G33, 'Padronização'!A:C, 3, FALSE), "") -> ABM/MAS focado em comportamento humano cognitivo | G33: I2 | H33: Não Relevante | L33: Não | M33: =IF(H33="","", IF(OR(H33="tornado",H33="vulcão",H33="enchente",H33="terremoto",H33="tsunami",H33="incêndio",H33="furacão",H33="deslizamento",H33="i. químico",H33="i. nuclear",H33="ataque",H33="guerra",H33="multirriscos"),2,0)+ IF(OR(I33="cidade",I33="regional",I33="urbano"),2,0)+ IF(J33="sim",2,IF(J33="parcial",1,0))+ IF(OR(K33="NetLogo",K33="Mesa",K33="GAMA",K33="Unity",K33="MATLAB",K33="Python"),2,0)+ IF(L33="sim",1,-10) ) -> -10 | N33: =IF(M33="","",IF(M33<=0,"EXCLUIR", IF(M33>=8,"ALTÍSSIMA", IF(M33>=6,"ALTA", IF(M33>=4,"MÉDIA", "BAIXA"))))) -> EXCLUIR
A34: Scopus | B34: 2025 | C34: Artigo | D34: Beyond Static Estimates: Dynamic Simulation of Fire–Evacuation Interaction in Historical Districts | E34: ✅ | F34: =IFERROR(VLOOKUP(G34, 'Padronização'!A:C, 3, FALSE), "") -> ABM/MAS aplicado à evacuação | G34: I1 | H34: Incêndio | I34: Regional | J34: Parcial | K34: Outro | L34: Sim | M34: =IF(H34="","", IF(OR(H34="tornado",H34="vulcão",H34="enchente",H34="terremoto",H34="tsunami",H34="incêndio",H34="furacão",H34="deslizamento",H34="i. químico",H34="i. nuclear",H34="ataque",H34="guerra",H34="multirriscos"),2,0)+ IF(OR(I34="cidade",I34="regional",I34="urbano"),2,0)+ IF(J34="sim",2,IF(J34="parcial",1,0))+ IF(OR(K34="NetLogo",K34="Mesa",K34="GAMA",K34="Unity",K34="MATLAB",K34="Python"),2,0)+ IF(L34="sim",1,-10) ) -> 6 | N34: =IF(M34="","",IF(M34<=0,"EXCLUIR", IF(M34>=8,"ALTÍSSIMA", IF(M34>=6,"ALTA", IF(M34>=4,"MÉDIA", "BAIXA"))))) -> ALTA
A35: Scopus | B35: 2025 | C35: Artigo | D35: A Bayesian agent-based model and software for wildfire safe evacuation planning and management | E35: ✅ | F35: =IFERROR(VLOOKUP(G35, 'Padronização'!A:C, 3, FALSE), "") -> ABM/MAS aplicado à evacuação | G35: I1 | H35: Não Relevante | L35: Não | M35: =IF(H35="","", IF(OR(H35="tornado",H35="vulcão",H35="enchente",H35="terremoto",H35="tsunami",H35="incêndio",H35="furacão",H35="deslizamento",H35="i. químico",H35="i. nuclear",H35="ataque",H35="guerra",H35="multirriscos"),2,0)+ IF(OR(I35="cidade",I35="regional",I35="urbano"),2,0)+ IF(J35="sim",2,IF(J35="parcial",1,0))+ IF(OR(K35="NetLogo",K35="Mesa",K35="GAMA",K35="Unity",K35="MATLAB",K35="Python"),2,0)+ IF(L35="sim",1,-10) ) -> -10 | N35: =IF(M35="","",IF(M35<=0,"EXCLUIR", IF(M35>=8,"ALTÍSSIMA", IF(M35>=6,"ALTA", IF(M35>=4,"MÉDIA", "BAIXA"))))) -> EXCLUIR
A36: Scopus | B36: 2025 | C36: Conference Paper | D36: Optimizing Shelter Site Locations in Residential Community: A Geo-Simulation and Genetic Algorithm Approach | E36: ✅ | F36: =IFERROR(VLOOKUP(G36, 'Padronização'!A:C, 3, FALSE), "") -> ABM/MAS aplicado à evacuação | G36: I1 | H36: Não Relevante | L36: Não | M36: =IF(H36="","", IF(OR(H36="tornado",H36="vulcão",H36="enchente",H36="terremoto",H36="tsunami",H36="incêndio",H36="furacão",H36="deslizamento",H36="i. químico",H36="i. nuclear",H36="ataque",H36="guerra",H36="multirriscos"),2,0)+ IF(OR(I36="cidade",I36="regional",I36="urbano"),2,0)+ IF(J36="sim",2,IF(J36="parcial",1,0))+ IF(OR(K36="NetLogo",K36="Mesa",K36="GAMA",K36="Unity",K36="MATLAB",K36="Python"),2,0)+ IF(L36="sim",1,-10) ) -> -10 | N36: =IF(M36="","",IF(M36<=0,"EXCLUIR", IF(M36>=8,"ALTÍSSIMA", IF(M36>=6,"ALTA", IF(M36>=4,"MÉDIA", "BAIXA"))))) -> EXCLUIR
A37: Scopus | B37: 2025 | C37: Artigo | D37: Modelling emergent pedestrian evacuation behaviors from intelligent, game-playing agents | E37: ✅ | F37: =IFERROR(VLOOKUP(G37, 'Padronização'!A:C, 3, FALSE), "") -> ABM/MAS aplicado à evacuação | G37: I1 | H37: Multirriscos | I37: Microescala | J37: Sim | K37: NetLogo | L37: Sim | M37: =IF(H37="","", IF(OR(H37="tornado",H37="vulcão",H37="enchente",H37="terremoto",H37="tsunami",H37="incêndio",H37="furacão",H37="deslizamento",H37="i. químico",H37="i. nuclear",H37="ataque",H37="guerra",H37="multirriscos"),2,0)+ IF(OR(I37="cidade",I37="regional",I37="urbano"),2,0)+ IF(J37="sim",2,IF(J37="parcial",1,0))+ IF(OR(K37="NetLogo",K37="Mesa",K37="GAMA",K37="Unity",K37="MATLAB",K37="Python"),2,0)+ IF(L37="sim",1,-10) ) -> 7 | N37: =IF(M37="","",IF(M37<=0,"EXCLUIR", IF(M37>=8,"ALTÍSSIMA", IF(M37>=6,"ALTA", IF(M37>=4,"MÉDIA", "BAIXA"))))) -> ALTA
A38: Scopus | B38: 2025 | C38: Artigo | D38: Crowd Evacuation Dynamics Under Shooting Attacks in Multi-Story Buildings | E38: ✅ | F38: =IFERROR(VLOOKUP(G38, 'Padronização'!A:C, 3, FALSE), "") -> ABM/MAS aplicado à evacuação | G38: I1 | H38: Ataque | I38: Microescala | J38: Sim | K38: NetLogo | L38: Sim | M38: =IF(H38="","", IF(OR(H38="tornado",H38="vulcão",H38="enchente",H38="terremoto",H38="tsunami",H38="incêndio",H38="furacão",H38="deslizamento",H38="i. químico",H38="i. nuclear",H38="ataque",H38="guerra",H38="multirriscos"),2,0)+ IF(OR(I38="cidade",I38="regional",I38="urbano"),2,0)+ IF(J38="sim",2,IF(J38="parcial",1,0))+ IF(OR(K38="NetLogo",K38="Mesa",K38="GAMA",K38="Unity",K38="MATLAB",K38="Python"),2,0)+ IF(L38="sim",1,-10) ) -> 7 | N38: =IF(M38="","",IF(M38<=0,"EXCLUIR", IF(M38>=8,"ALTÍSSIMA", IF(M38>=6,"ALTA", IF(M38>=4,"MÉDIA", "BAIXA"))))) -> ALTA
A39: Scopus | B39: 2025 | C39: Artigo | D39: Assessing the impact of early warning and evacuation on human losses during the 2021 Ahr Valley flood in Germany using agent-based modelling | E39: ✅ | F39: =IFERROR(VLOOKUP(G39, 'Padronização'!A:C, 3, FALSE), "") -> ABM/MAS aplicado à evacuação | G39: I1 | H39: Enchente | I39: Regional | J39: Sim | K39: Outro | L39: Sim | M39: =IF(H39="","", IF(OR(H39="tornado",H39="vulcão",H39="enchente",H39="terremoto",H39="tsunami",H39="incêndio",H39="furacão",H39="deslizamento",H39="i. químico",H39="i. nuclear",H39="ataque",H39="guerra",H39="multirriscos"),2,0)+ IF(OR(I39="cidade",I39="regional",I39="urbano"),2,0)+ IF(J39="sim",2,IF(J39="parcial",1,0))+ IF(OR(K39="NetLogo",K39="Mesa",K39="GAMA",K39="Unity",K39="MATLAB",K39="Python"),2,0)+ IF(L39="sim",1,-10) ) -> 7 | N39: =IF(M39="","",IF(M39<=0,"EXCLUIR", IF(M39>=8,"ALTÍSSIMA", IF(M39>=6,"ALTA", IF(M39>=4,"MÉDIA", "BAIXA"))))) -> ALTA
A40: Scopus | B40: 2025 | C40: Artigo | D40: A congestion prediction model for optimizing emergency evacuation design of university libraries in China | E40: ✅ | F40: =IFERROR(VLOOKUP(G40, 'Padronização'!A:C, 3, FALSE), "") -> ABM/MAS aplicado à evacuação | G40: I1 | H40: Multirriscos | I40: Microescala | J40: Parcial | K40: Outro | L40: Sim | M40: =IF(H40="","", IF(OR(H40="tornado",H40="vulcão",H40="enchente",H40="terremoto",H40="tsunami",H40="incêndio",H40="furacão",H40="deslizamento",H40="i. químico",H40="i. nuclear",H40="ataque",H40="guerra",H40="multirriscos"),2,0)+ IF(OR(I40="cidade",I40="regional",I40="urbano"),2,0)+ IF(J40="sim",2,IF(J40="parcial",1,0))+ IF(OR(K40="NetLogo",K40="Mesa",K40="GAMA",K40="Unity",K40="MATLAB",K40="Python"),2,0)+ IF(L40="sim",1,-10) ) -> 4 | N40: =IF(M40="","",IF(M40<=0,"EXCLUIR", IF(M40>=8,"ALTÍSSIMA", IF(M40>=6,"ALTA", IF(M40>=4,"MÉDIA", "BAIXA"))))) -> MÉDIA
A41: Scopus | B41: 2025 | C41: Artigo | D41: Large-scale real-time evacuation modeling during urban floods: A coupled agent-based multi-model framework | E41: ✅ | F41: =IFERROR(VLOOKUP(G41, 'Padronização'!A:C, 3, FALSE), "") -> ABM/MAS aplicado à evacuação | G41: I1 | H41: Enchente | I41: Regional | J41: Sim | K41: NetLogo | L41: Sim | M41: =IF(H41="","", IF(OR(H41="tornado",H41="vulcão",H41="enchente",H41="terremoto",H41="tsunami",H41="incêndio",H41="furacão",H41="deslizamento",H41="i. químico",H41="i. nuclear",H41="ataque",H41="guerra",H41="multirriscos"),2,0)+ IF(OR(I41="cidade",I41="regional",I41="urbano"),2,0)+ IF(J41="sim",2,IF(J41="parcial",1,0))+ IF(OR(K41="NetLogo",K41="Mesa",K41="GAMA",K41="Unity",K41="MATLAB",K41="Python"),2,0)+ IF(L41="sim",1,-10) ) -> 9 | N41: =IF(M41="","",IF(M41<=0,"EXCLUIR", IF(M41>=8,"ALTÍSSIMA", IF(M41>=6,"ALTA", IF(M41>=4,"MÉDIA", "BAIXA"))))) -> ALTÍSSIMA
A42: Scopus | B42: 2025 | C42: Artigo | D42: Improving evacuation policies through agent-based modeling and stakeholder engagement in hazard-prone areas | E42: ✅ | F42: =IFERROR(VLOOKUP(G42, 'Padronização'!A:C, 3, FALSE), "") -> ABM/MAS aplicado à evacuação | G42: I1 | H42: Multirriscos | I42: Regional | J42: Sim | K42: Outro | L42: Sim | M42: =IF(H42="","", IF(OR(H42="tornado",H42="vulcão",H42="enchente",H42="terremoto",H42="tsunami",H42="incêndio",H42="furacão",H42="deslizamento",H42="i. químico",H42="i. nuclear",H42="ataque",H42="guerra",H42="multirriscos"),2,0)+ IF(OR(I42="cidade",I42="regional",I42="urbano"),2,0)+ IF(J42="sim",2,IF(J42="parcial",1,0))+ IF(OR(K42="NetLogo",K42="Mesa",K42="GAMA",K42="Unity",K42="MATLAB",K42="Python"),2,0)+ IF(L42="sim",1,-10) ) -> 7 | N42: =IF(M42="","",IF(M42<=0,"EXCLUIR", IF(M42>=8,"ALTÍSSIMA", IF(M42>=6,"ALTA", IF(M42>=4,"MÉDIA", "BAIXA"))))) -> ALTA
A43: Scopus | B43: 2025 | C43: Artigo | D43: Modeling residents’ long-term adaptation to geohazards in mountainous regions using agent-based models and Bayesian networks | E43: ✅ | F43: =IFERROR(VLOOKUP(G43, 'Padronização'!A:C, 3, FALSE), "") -> ABM/MAS focado em comportamento humano cognitivo | G43: I2 | H43: Multirriscos | I43: Regional | J43: Sim | K43: NetLogo | L43: Sim | M43: =IF(H43="","", IF(OR(H43="tornado",H43="vulcão",H43="enchente",H43="terremoto",H43="tsunami",H43="incêndio",H43="furacão",H43="deslizamento",H43="i. químico",H43="i. nuclear",H43="ataque",H43="guerra",H43="multirriscos"),2,0)+ IF(OR(I43="cidade",I43="regional",I43="urbano"),2,0)+ IF(J43="sim",2,IF(J43="parcial",1,0))+ IF(OR(K43="NetLogo",K43="Mesa",K43="GAMA",K43="Unity",K43="MATLAB",K43="Python"),2,0)+ IF(L43="sim",1,-10) ) -> 9 | N43: =IF(M43="","",IF(M43<=0,"EXCLUIR", IF(M43>=8,"ALTÍSSIMA", IF(M43>=6,"ALTA", IF(M43>=4,"MÉDIA", "BAIXA"))))) -> ALTÍSSIMA
...

Sheet Camada 3
A1: Fonte | B1: Ano | C1: Tipo | D1: Título | E1: Decisão C1 | F1: Motivo | G1: Código | H1: Tipo de Crise | I1: Escala | J1: C. Humano | K1: Ferramenta | L1: Disponível | M1: Score | N1: Prioridade | O1: Leitura Completa | P1: Motivo Exclusão | Q1: Incluir
A2: Scopus | B2: 2026 | C2: Artigo | D2: Dynamic Human-Vehicle Risk Assessment for Urban Flood Evacuations in Island Cities: The MUFE Framework Applied to Haidian Island, Haikou | E2: ✅ | F2: =IFERROR(VLOOKUP(G2, 'Padronização'!A:C, 3, FALSE), "") -> ABM/MAS focado em comportamento humano cognitivo | G2: I2 | H2: Enchente | I2: Regional | J2: Sim | K2: Mesa | L2: Sim | M2: =IF(H2="","", IF(OR(H2="tornado",H2="vulcão",H2="enchente",H2="terremoto",H2="tsunami",H2="incêndio",H2="furacão",H2="deslizamento",H2="i. químico",H2="i. nuclear",H2="ataque",H2="guerra",H2="multirriscos"),2,0)+ IF(OR(I2="cidade",I2="regional",I2="urbano"),2,0)+ IF(J2="sim",2,IF(J2="parcial",1,0))+ IF(OR(K2="NetLogo",K2="Mesa",K2="GAMA",K2="Unity",K2="MATLAB",K2="Python"),2,0)+ IF(L2="sim",1,-10) ) -> 9 | N2: =IF(M2="","",IF(M2<=0,"EXCLUIR", IF(M2>=8,"ALTÍSSIMA", IF(M2>=6,"ALTA", IF(M2>=4,"MÉDIA", "BAIXA"))))) -> ALTÍSSIMA | O2: Sim | P2: Foco em avaliação de risco e estabilidade de veículos, sem modelagem direta do processo de evacuação | Q2: Não
A3: Scopus | B3: 2026 | C3: Artigo | D3: Enhancing urban flood resilience through agent-based modeling of evacuation behaviors | E3: ✅ | F3: =IFERROR(VLOOKUP(G3, 'Padronização'!A:C, 3, FALSE), "") -> ABM/MAS focado em comportamento humano cognitivo | G3: I2 | H3: Enchente | I3: Regional | J3: Sim | K3: NetLogo | L3: Sim | M3: =IF(H3="","", IF(OR(H3="tornado",H3="vulcão",H3="enchente",H3="terremoto",H3="tsunami",H3="incêndio",H3="furacão",H3="deslizamento",H3="i. químico",H3="i. nuclear",H3="ataque",H3="guerra",H3="multirriscos"),2,0)+ IF(OR(I3="cidade",I3="regional",I3="urbano"),2,0)+ IF(J3="sim",2,IF(J3="parcial",1,0))+ IF(OR(K3="NetLogo",K3="Mesa",K3="GAMA",K3="Unity",K3="MATLAB",K3="Python"),2,0)+ IF(L3="sim",1,-10) ) -> 9 | N3: =IF(M3="","",IF(M3<=0,"EXCLUIR", IF(M3>=8,"ALTÍSSIMA", IF(M3>=6,"ALTA", IF(M3>=4,"MÉDIA", "BAIXA"))))) -> ALTÍSSIMA | O3: Não | P3: Self-evecuate | Q3: Não
A4: Scopus | B4: 2025 | C4: Artigo | D4: Urban waterlogging disaster risk evaluation framework based on complex network and agent-based model: a case study of Zhengzhou, China | E4: ✅ | F4: =IFERROR(VLOOKUP(G4, 'Padronização'!A:C, 3, FALSE), "") -> ABM/MAS focado em comportamento humano cognitivo | G4: I2 | H4: Enchente | I4: Regional | J4: Sim | K4: NetLogo | L4: Sim | M4: =IF(H4="","", IF(OR(H4="tornado",H4="vulcão",H4="enchente",H4="terremoto",H4="tsunami",H4="incêndio",H4="furacão",H4="deslizamento",H4="i. químico",H4="i. nuclear",H4="ataque",H4="guerra",H4="multirriscos"),2,0)+ IF(OR(I4="cidade",I4="regional",I4="urbano"),2,0)+ IF(J4="sim",2,IF(J4="parcial",1,0))+ IF(OR(K4="NetLogo",K4="Mesa",K4="GAMA",K4="Unity",K4="MATLAB",K4="Python"),2,0)+ IF(L4="sim",1,-10) ) -> 9 | N4: =IF(M4="","",IF(M4<=0,"EXCLUIR", IF(M4>=8,"ALTÍSSIMA", IF(M4>=6,"ALTA", IF(M4>=4,"MÉDIA", "BAIXA"))))) -> ALTÍSSIMA | O4: Não | P4: Redes de transporte (metro, tuneis etc) | Q4: Não
A5: Scopus | B5: 2025 | C5: Artigo | D5: FRAMe: Empirically informed agent-based modeling of flood resilience in the Mekong River Basin | E5: ✅ | F5: =IFERROR(VLOOKUP(G5, 'Padronização'!A:C, 3, FALSE), "") -> ABM/MAS focado em comportamento humano cognitivo | G5: I2 | H5: Enchente | I5: Regional | J5: Sim | K5: NetLogo | L5: Sim | M5: =IF(H5="","", IF(OR(H5="tornado",H5="vulcão",H5="enchente",H5="terremoto",H5="tsunami",H5="incêndio",H5="furacão",H5="deslizamento",H5="i. químico",H5="i. nuclear",H5="ataque",H5="guerra",H5="multirriscos"),2,0)+ IF(OR(I5="cidade",I5="regional",I5="urbano"),2,0)+ IF(J5="sim",2,IF(J5="parcial",1,0))+ IF(OR(K5="NetLogo",K5="Mesa",K5="GAMA",K5="Unity",K5="MATLAB",K5="Python"),2,0)+ IF(L5="sim",1,-10) ) -> 9 | N5: =IF(M5="","",IF(M5<=0,"EXCLUIR", IF(M5>=8,"ALTÍSSIMA", IF(M5>=6,"ALTA", IF(M5>=4,"MÉDIA", "BAIXA"))))) -> ALTÍSSIMA | O5: Não | P5: pré- -pós | Q5: Não
A6: Scopus | B6: 2025 | C6: Artigo | D6: Enhancing local flood resilience: A participatory simulation-game framework for evacuation planning in Thailand | E6: ✅ | F6: =IFERROR(VLOOKUP(G6, 'Padronização'!A:C, 3, FALSE), "") -> ABM/MAS aplicado à evacuação | G6: I1 | H6: Enchente | I6: Regional | J6: Sim | K6: GAMA | L6: Sim | M6: =IF(H6="","", IF(OR(H6="tornado",H6="vulcão",H6="enchente",H6="terremoto",H6="tsunami",H6="incêndio",H6="furacão",H6="deslizamento",H6="i. químico",H6="i. nuclear",H6="ataque",H6="guerra",H6="multirriscos"),2,0)+ IF(OR(I6="cidade",I6="regional",I6="urbano"),2,0)+ IF(J6="sim",2,IF(J6="parcial",1,0))+ IF(OR(K6="NetLogo",K6="Mesa",K6="GAMA",K6="Unity",K6="MATLAB",K6="Python"),2,0)+ IF(L6="sim",1,-10) ) -> 9 | N6: =IF(M6="","",IF(M6<=0,"EXCLUIR", IF(M6>=8,"ALTÍSSIMA", IF(M6>=6,"ALTA", IF(M6>=4,"MÉDIA", "BAIXA"))))) -> ALTÍSSIMA | O6: Sim | Q6: Sim
A7: Scopus | B7: 2025 | C7: Artigo | D7: Flood-ABM: An agent-based model of differential flood effects on population groups and their decision-making processes | E7: ✅ | F7: =IFERROR(VLOOKUP(G7, 'Padronização'!A:C, 3, FALSE), "") -> Resposta humana a alertas e decisões | G7: I3 | H7: Enchente | I7: Regional | J7: Sim | K7: Mesa | L7: Sim | M7: =IF(H7="","", IF(OR(H7="tornado",H7="vulcão",H7="enchente",H7="terremoto",H7="tsunami",H7="incêndio",H7="furacão",H7="deslizamento",H7="i. químico",H7="i. nuclear",H7="ataque",H7="guerra",H7="multirriscos"),2,0)+ IF(OR(I7="cidade",I7="regional",I7="urbano"),2,0)+ IF(J7="sim",2,IF(J7="parcial",1,0))+ IF(OR(K7="NetLogo",K7="Mesa",K7="GAMA",K7="Unity",K7="MATLAB",K7="Python"),2,0)+ IF(L7="sim",1,-10) ) -> 9 | N7: =IF(M7="","",IF(M7<=0,"EXCLUIR", IF(M7>=8,"ALTÍSSIMA", IF(M7>=6,"ALTA", IF(M7>=4,"MÉDIA", "BAIXA"))))) -> ALTÍSSIMA | O7: Não | P7: envolve questões sócio-economicas | Q7: Não
A8: Scopus | B8: 2025 | C8: Artigo | D8: Resident Participation in Flood Response: A Machine Learning and Agent-Based Simulation Study of Zhengzhou, China | E8: ✅ | F8: =IFERROR(VLOOKUP(G8, 'Padronização'!A:C, 3, FALSE), "") -> ABM/MAS focado em comportamento humano cognitivo | G8: I2 | H8: Enchente | I8: Regional | J8: Sim | K8: Outro | L8: Sim | M8: =IF(H8="","", IF(OR(H8="tornado",H8="vulcão",H8="enchente",H8="terremoto",H8="tsunami",H8="incêndio",H8="furacão",H8="deslizamento",H8="i. químico",H8="i. nuclear",H8="ataque",H8="guerra",H8="multirriscos"),2,0)+ IF(OR(I8="cidade",I8="regional",I8="urbano"),2,0)+ IF(J8="sim",2,IF(J8="parcial",1,0))+ IF(OR(K8="NetLogo",K8="Mesa",K8="GAMA",K8="Unity",K8="MATLAB",K8="Python"),2,0)+ IF(L8="sim",1,-10) ) -> 7 | N8: =IF(M8="","",IF(M8<=0,"EXCLUIR", IF(M8>=8,"ALTÍSSIMA", IF(M8>=6,"ALTA", IF(M8>=4,"MÉDIA", "BAIXA"))))) -> ALTA | O8: Não | P8: predição de comportamento | Q8: Não
A9: Scopus | B9: 2025 | C9: Artigo | D9: Dynamic flood evacuation modelling for coastal cities: A case study of Shanghai | E9: ✅ | F9: =IFERROR(VLOOKUP(G9, 'Padronização'!A:C, 3, FALSE), "") -> ABM/MAS aplicado à evacuação | G9: I1 | H9: Enchente | I9: Regional | J9: Sim | K9: NetLogo | L9: Sim | M9: =IF(H9="","", IF(OR(H9="tornado",H9="vulcão",H9="enchente",H9="terremoto",H9="tsunami",H9="incêndio",H9="furacão",H9="deslizamento",H9="i. químico",H9="i. nuclear",H9="ataque",H9="guerra",H9="multirriscos"),2,0)+ IF(OR(I9="cidade",I9="regional",I9="urbano"),2,0)+ IF(J9="sim",2,IF(J9="parcial",1,0))+ IF(OR(K9="NetLogo",K9="Mesa",K9="GAMA",K9="Unity",K9="MATLAB",K9="Python"),2,0)+ IF(L9="sim",1,-10) ) -> 9 | N9: =IF(M9="","",IF(M9<=0,"EXCLUIR", IF(M9>=8,"ALTÍSSIMA", IF(M9>=6,"ALTA", IF(M9>=4,"MÉDIA", "BAIXA"))))) -> ALTÍSSIMA | O9: Sim | Q9: Sim
A10: Scopus | B10: 2025 | C10: Artigo | D10: Assessing the impact of early warning and evacuation on human losses during the 2021 Ahr Valley flood in Germany using agent-based modelling | E10: ✅ | F10: =IFERROR(VLOOKUP(G10, 'Padronização'!A:C, 3, FALSE), "") -> ABM/MAS aplicado à evacuação | G10: I1 | H10: Enchente | I10: Regional | J10: Sim | K10: Outro | L10: Sim | M10: =IF(H10="","", IF(OR(H10="tornado",H10="vulcão",H10="enchente",H10="terremoto",H10="tsunami",H10="incêndio",H10="furacão",H10="deslizamento",H10="i. químico",H10="i. nuclear",H10="ataque",H10="guerra",H10="multirriscos"),2,0)+ IF(OR(I10="cidade",I10="regional",I10="urbano"),2,0)+ IF(J10="sim",2,IF(J10="parcial",1,0))+ IF(OR(K10="NetLogo",K10="Mesa",K10="GAMA",K10="Unity",K10="MATLAB",K10="Python"),2,0)+ IF(L10="sim",1,-10) ) -> 7 | N10: =IF(M10="","",IF(M10<=0,"EXCLUIR", IF(M10>=8,"ALTÍSSIMA", IF(M10>=6,"ALTA", IF(M10>=4,"MÉDIA", "BAIXA"))))) -> ALTA | O10: Não | P10: Não aparenta ser bom suporte técnico | Q10: Não
A11: Scopus | B11: 2025 | C11: Artigo | D11: Large-scale real-time evacuation modeling during urban floods: A coupled agent-based multi-model framework | E11: ✅ | F11: =IFERROR(VLOOKUP(G11, 'Padronização'!A:C, 3, FALSE), "") -> ABM/MAS aplicado à evacuação | G11: I1 | H11: Enchente | I11: Regional | J11: Sim | K11: NetLogo | L11: Sim | M11: =IF(H11="","", IF(OR(H11="tornado",H11="vulcão",H11="enchente",H11="terremoto",H11="tsunami",H11="incêndio",H11="furacão",H11="deslizamento",H11="i. químico",H11="i. nuclear",H11="ataque",H11="guerra",H11="multirriscos"),2,0)+ IF(OR(I11="cidade",I11="regional",I11="urbano"),2,0)+ IF(J11="sim",2,IF(J11="parcial",1,0))+ IF(OR(K11="NetLogo",K11="Mesa",K11="GAMA",K11="Unity",K11="MATLAB",K11="Python"),2,0)+ IF(L11="sim",1,-10) ) -> 9 | N11: =IF(M11="","",IF(M11<=0,"EXCLUIR", IF(M11>=8,"ALTÍSSIMA", IF(M11>=6,"ALTA", IF(M11>=4,"MÉDIA", "BAIXA"))))) -> ALTÍSSIMA | O11: Sim | Q11: Sim
A12: Scopus | B12: 2024 | C12: Artigo | D12: Dynamic disaster risk assessment of urban waterlogging on pedestrian flow by intelligent simulation of hydrodynamics coupled with agent-based models in Chao-yang river basin of Nanning, China | E12: ✅ | F12: =IFERROR(VLOOKUP(G12, 'Padronização'!A:C, 3, FALSE), "") -> ABM/MAS focado em comportamento humano cognitivo | G12: I2 | H12: Enchente | I12: Regional | J12: Sim | K12: NetLogo | L12: Sim | M12: =IF(H12="","", IF(OR(H12="tornado",H12="vulcão",H12="enchente",H12="terremoto",H12="tsunami",H12="incêndio",H12="furacão",H12="deslizamento",H12="i. químico",H12="i. nuclear",H12="ataque",H12="guerra",H12="multirriscos"),2,0)+ IF(OR(I12="cidade",I12="regional",I12="urbano"),2,0)+ IF(J12="sim",2,IF(J12="parcial",1,0))+ IF(OR(K12="NetLogo",K12="Mesa",K12="GAMA",K12="Unity",K12="MATLAB",K12="Python"),2,0)+ IF(L12="sim",1,-10) ) -> 9 | N12: =IF(M12="","",IF(M12<=0,"EXCLUIR", IF(M12>=8,"ALTÍSSIMA", IF(M12>=6,"ALTA", IF(M12>=4,"MÉDIA", "BAIXA"))))) -> ALTÍSSIMA | O12: Não | Q12: Não
A13: Scopus | B13: 2024 | C13: Artigo | D13: Unraveling the interplay of human decisions and flood risk: An agent-based modeling approach | E13: ✅ | F13: =IFERROR(VLOOKUP(G13, 'Padronização'!A:C, 3, FALSE), "") -> ABM/MAS focado em comportamento humano cognitivo | G13: I2 | H13: Enchente | I13: Regional | J13: Sim | K13: Outro | L13: Sim | M13: =IF(H13="","", IF(OR(H13="tornado",H13="vulcão",H13="enchente",H13="terremoto",H13="tsunami",H13="incêndio",H13="furacão",H13="deslizamento",H13="i. químico",H13="i. nuclear",H13="ataque",H13="guerra",H13="multirriscos"),2,0)+ IF(OR(I13="cidade",I13="regional",I13="urbano"),2,0)+ IF(J13="sim",2,IF(J13="parcial",1,0))+ IF(OR(K13="NetLogo",K13="Mesa",K13="GAMA",K13="Unity",K13="MATLAB",K13="Python"),2,0)+ IF(L13="sim",1,-10) ) -> 7 | N13: =IF(M13="","",IF(M13<=0,"EXCLUIR", IF(M13>=8,"ALTÍSSIMA", IF(M13>=6,"ALTA", IF(M13>=4,"MÉDIA", "BAIXA"))))) -> ALTA | O13: Não | P13: socioeconomico (fazendas) | Q13: Não
A14: Scopus | B14: 2024 | C14: Artigo | D14: Understanding Tsunami Evacuation via a Social Force Model While Considering Stress Levels Using Agent-Based Modelling | E14: ✅ | F14: =IFERROR(VLOOKUP(G14, 'Padronização'!A:C, 3, FALSE), "") -> ABM/MAS aplicado à evacuação | G14: I1 | H14: Tsunami | I14: Regional | J14: Sim | K14: NetLogo | L14: Sim | M14: =IF(H14="","", IF(OR(H14="tornado",H14="vulcão",H14="enchente",H14="terremoto",H14="tsunami",H14="incêndio",H14="furacão",H14="deslizamento",H14="i. químico",H14="i. nuclear",H14="ataque",H14="guerra",H14="multirriscos"),2,0)+ IF(OR(I14="cidade",I14="regional",I14="urbano"),2,0)+ IF(J14="sim",2,IF(J14="parcial",1,0))+ IF(OR(K14="NetLogo",K14="Mesa",K14="GAMA",K14="Unity",K14="MATLAB",K14="Python"),2,0)+ IF(L14="sim",1,-10) ) -> 9 | N14: =IF(M14="","",IF(M14<=0,"EXCLUIR", IF(M14>=8,"ALTÍSSIMA", IF(M14>=6,"ALTA", IF(M14>=4,"MÉDIA", "BAIXA"))))) -> ALTÍSSIMA
